Testing "my error test function" in mytest.t.cc:
! mytest.t.cc:432     thing.works()         ok
This is just some crap that I printed while counting to 3.
! mytest.t.cc.433     3 < 4                 FAILED

